Workbook

Sheet 1-填表说明和指标解释
A1: 填写规则
A2: 一、“ICT投资效益评估表”共4部分，包括填表说明和指标解释、ICT项目评估结果、直接经济效益评估表、专线及产品预算表（建设+维护）。
A3: 二、需填写部分：ICT项目评估结果、直接经济效益评估表、专线及各产品预算表（建设+维护）。
A4: 三、项目收入：包含IT收入和CT收入。“合同约定收款”应为依据与客户方合同，在合同期限内我公司确认取得的收入总额。确认项目现金流入时，应考虑项目建设期及业务实际开通时间等因素，从实际产生收入之时开始计算各项收入，并按合同付费要求按年填写实际现金流。
A5: 四、项目支出：包含IT支出、CT支出和其他支出。 项目成本支出应完整考虑合同期内所有相关建设、维护、更新等费用，按实际支出发生时间计入项目现金流出。“IT部分支出”包括“建设/服务支出”、“运行维护费用”、“其他支出”。“运行维护费用”应包含合同期内的所有运行维护支出，包括维护费用、设备更新费用、等其他需由我公司支付的费用。原则上在与合作方签订ICT项目协议时，其维保条件应满足我公司与客户单位协议中的维护标准及时限要求。若合作方提供的维保不能满足业主需求，确需增加维保的，该部分的维保成本应包含在维护费用内。综合类成本，指社会渠道酬金、相关管理费用等；非本项目新增支出成本分摊指IT/CT的量纲、间接成本分摊。
A6: 五、请需求单位根据实际情况填写。
A7: 指标解释
A8: 序号 | B8: 指标名称 | C8: 评价体系 | D8: 定义 | E8: 计算方法
A9: 1 | B9: 项目净现值 | C9: 集团/省内要求指标 | D9: 项目未来现金流入现值与未来现金流出现值的差额 | E9: 项目现金流入现值-项目现金流出现值
A11: 2 | B11: 净现值率 | C11: 集团/省内要求指标 | D11: 项目净现值与总投资现值的比率 | E11: 净现值率=净现值/项目总投资现值*100%，净现值为建设期及生产期各年净现金流量现值合计值，总投资现值为建设及生产期内的投资现金流出的累计现值。
A12: 3 | B12: 项目毛利率 （项目整体利润率） | C12: 集团/省内要求指标 | D12: 项目毛利与项目收入的比率 | E12: 毛利率=毛利/项目总收入*100%，毛利=收入-投入。
A13: 4 | B13: 动态回收期 | C13: 集团/省内要求指标 | D13: 考虑资金的时间价值时收回初始投入所需的时间。 | E13: （累计净现金流量现值最后一次转正值的月份-1）+上一月累计净现金流量现值的绝对值/最后一次转正值月份净现金流量的现值。
A15: 5 | B15: 内部收益率 | C15: 集团要求指标 | D15: 资金流入现值总额与资金流出现值总额相等、净现值等于零时的折现率。 | E15: 根据接近于零的相邻正负两个净现值的折现率i1、i2，相应的净现值为NPV1、NPV2，用线性内插法求得内部收益率。内插公式为：IRR=i1+NPV1(i2-i1)/(NPV1-NPV2)。
A16: 6 | B16: IT净现值率 | C16: 省内要求指标 | D16: IT净现值与原始IT投入现值的比率 | E16: IT净现值率=IT净现值/IT总投入现值*100%
A17: 7 | B17: 静态回收期 | C17: 集团/省内要求指标 | D17: 不考虑资金的时间价值时，收回初始投入所需的时间 | E17: （累计净现金流量最后一次转正值的月份-1）+上一月累计净现金流量的绝对值/最后一次转正值月份现金流量指。
A18: 8 | B18: IT毛利率 （IT部分利润率） | C18: 集团/省内要求指标 | D18: IT毛利与IT收入的比率 | E18: IT毛利率=(IT收入-IT成本）/IT收入
A19: 9 | B19: 项目整体直接毛利率 | C19: 集团要求指标 | D19: 指直接毛利与项目收入的比率。 | E19: 直接毛利指项目收入减去项目支出（不含综合类成本和非本项目新增支出成本分摊）后的余额。
A20: 10 | B20: IT部分直接毛利率 | C20: 集团要求指标 | D20: 指IT部分利润与项目收入的比率。I | E20: IT类项目收入减去IT类项目支出（不含综合类成本和非本项目新增支出成本分摊）后的余额。
A21: 11 | B21: IT服务部分直接毛利率 | C21: 集团要求指标 | D21: 指IT服务部分直接毛利与项目收入的比率。 | E21: IT服务部分直接毛利指IT类项目收入中服务部分减去IT类项目支出中服务部分（不含综合类成本和非本项目新增支出成本分摊）后的余额。
A22: 12 | B22: 项目通服直接毛利率 | C22: 集团要求指标 | D22: 指通服直接毛利与项目通服收入的比率。 | E22: 项目通服收入减去项目支出（不含硬件类成本、综合类成本和非本项目新增支出成本分摊）后的余额。

Sheet 2-ICT项目评估结果
A2: ICT项目效益评估
A3: 项目基本信息 | C3: 相关人员确认
A4: 项目名称 | B4: 重庆高新智算科技服务有限公司机房改造项目
A5: 客户单位名称 | B5: 重庆高新智算科技服务有限公司
A6: 是否为续签项目 | B6: 否
A7: 商务模式 | B7: 服务购销
A8: 合同年限（年） | B8: 2
A9: 资金来源 | B9: 成本
A10: 项目总投入（元/不含税） | B10: ='3-直接经济效益评估表'!G31 -> 7384.57
A11: IT投入（建设+维护） | B11: =SUM('3-直接经济效益评估表'!G11:G20) -> 6839.62
A12: CT实际投入（建设+维护） | B12: =SUM('3-直接经济效益评估表'!G21:G26) -> 544.95
A13: 非IT/CT投入 | B13: =SUM('3-直接经济效益评估表'!G27) -> 0
A14: 综合类成本 | B14: =SUM('3-直接经济效益评估表'!G28:G30) -> 0
A15: 项目总收入（元/不含税） | B15: ='3-直接经济效益评估表'!G10 -> 8075.78
A16: IT收入 | B16: =SUM('3-直接经济效益评估表'!G3:G6) -> 6886.79
A17: CT收入 | B17: =SUM('3-直接经济效益评估表'!G7:G8) -> 1188.99
A18: 非IT/CT收入 | B18: ='3-直接经济效益评估表'!G5 -> 0
A19: 项目效益评估结果
A20: 评价指标 | B20: 评估结果
A21: 折现率 | B21: 0.055
A22: 项目净现值（元） | B22: ='3-直接经济效益评估表'!C44 -> 621.63
A23: 项目净现值率（%) | B23: ='3-直接经济效益评估表'!C46 -> 0.0936
A24: 动态回收期（年） | B24: ='3-直接经济效益评估表'!C45 -> 1
A25: 项目毛利率（%） | B25: ='3-直接经济效益评估表'!C48 -> 0.0856
A26: 内部收益率（%）（投资模式） | B26: ='3-直接经济效益评估表'!C47 -> #NUM!
A27: IT净现值率（%） | B27: ='3-直接经济效益评估表'!C64 -> 0.0069
A28: 静态回收期（年） | B28: ='3-直接经济效益评估表'!C49 -> 1
A29: IT毛利率 | B29: ='3-直接经济效益评估表'!C65 -> 0.0068
B30: 立项决策层级
A31: 根据项目投入金额和效益评估结果进行分级授权决策 | B31: 公司总办会决策
A33: 业务价值评估
A34: 评价指标 | B34: 指标说明 | C34: 指标达成情况描述
A35: 客户规模 | B35: 主要评价集团客户的级别，规模和影响力。 | C35: A类集团
A36: 标杆效应及对CT拉动效应分析 | B36: 主要考核项目对于行业的影响作用；对CT拉动的影响作用。 | C36: 无
A37: 政府重点建设项目 | B37: 主要考核政府对于项目的重视程度。 | C37: 是
A38: 项目可能涉及5G应用场景的复制 | B38: 主要评价项目是否涉及5G应用场景，能否复制已有的应用场景，并对5G应用场景有其他方面的扩展。 | C38: 不涉及
A39: 对市场占有率的影响 | B39: 主要评价项目投资对于扩大市场占有率和影响力的带动作用。 | C39: 提升移动份额
A40: 其他业务价值 | B40: 如有其他业务价值，可视需求增加，请自行补充。 | C40: 无

Sheet 3-直接经济效益评估表
B1: 分表：经济效益评估表（2025版）（所有数据请按照不含税填写）
A2: 项目概况 | C2: 项目名称 | D2: 达丰重庆电脑有限公司AI智能体项目 | G2: 产权归属 | H2: 不涉及
D3: 集成服务 | G3: =Q3/1.06 -> 6886.79 | H3: 测算说明 | J3: 系统集成服务税率6% | Q3: =Q10-Q8 -> 7300
D4: 设备租赁收入 | H4: 测算说明 | I4: 请明确税率
D5: 其他收入（代销设备、代理采购手续费等） | H5: 测算说明 | I5: 工程施工税率9% | Q5: =ROUND(G5*1.09,2) -> 0
D6: 移动云-定制化收入 | H6: 测算说明 | I6: 请明确税率
C7: CT收入 | D7: 专线收入 | G7: 0 | H7: 测算说明 | I7: 请明确税率
D8: 产品收入 | G8: =Q8/1.09 -> 1188.99 | H8: 测算说明 | I8: 请明确税率 | Q8: 1296
C9: 非IT/CT收入 | D9: 工程施工收入等 | H9: 测算说明
C10: 总计 | D10: IT/云收入+CT收入+非IT/CT收入 | G10: =SUM(G3:G8) -> 8075.78 | Q10: 8596
A11: 支出侧合同 约定支出 | C11: IT/移动云投入 | D11: 建设/服务支出 | E11: 主要设备/甲供材料 | G11: 0 | H11: 测算说明 | I11: 硬件设备销售收入税率13% | Q11: 0
E12: 施工 | G12: 0 | H12: 测算说明 | I12: 工程施工税率9% | Q12: 0
E13: 勘察设计/预备费 | H13: 测算说明 | I13: 请明确税率
E14: 集成服务 | G14: =Q14/1.06 -> 6839.62 | H14: 测算说明 | I14: 系统集成服务税率6% | Q14: 7250
E15: 其他投入 | H15: 测算说明 | I15: 请明确税率
D16: 运行维护费用 | E16: 维护费用 | H16: 测算说明 | I16: 请明确税率
E17: 其他运行支出（电费等） | H17: 测算说明 | I17: 请明确税率
D18: 其他投入 | E18: 中标服务费 | H18: 测算说明 | I18: 请明确税率
E19: 设计院成本评估费 | H19: 测算说明 | I19: 评估费，税率为6%
E20: 数智化转型咨询服务 | G20: 0 | H20: 测算说明 | I20: 设计院评估费，税率6% | Q20: 0
C21: CT投入 | D21: CT实际投入 | E21: 专线建设 | H21: 测算说明 | I21: 请明确该项具体类别及税率
E22: 专线维护 | G22: =Q22/1.09 -> 544.95 | H22: 测算说明 | I22: 根据公司采购结果据实测算 | Q22: 594
E23: 其他产品成本 （具体测算规则详见Sheet5） | G23: 0 | H23: 测算说明 | Q23: 0
E24: 其他产品成本 （具体测算规则详见Sheet5） | H24: 测算说明
D25: CT虚拟投入 （续签需考虑） | E25: 专线带宽成本 | H25: 测算说明 | I25: 请明确该项具体类别及税率
E26: 专线/其他产品续签成本 | H26: 测算说明 | I26: 请明确该项具体类别及税率
C27: 非IT/CT投入 | D27: 工程施工投入 | E27: 工程施工投入等 | H27: 测算说明 | I27: 请明确该项具体类别及税率 | AB27: =174000/0.2785 -> 624775.58
C28: 综合类成本 | D28: 融合营销成本 | H28: 测算说明
D29: 渠道酬金 | H29: 测算说明
D30: 其他管理费用等 | H30: 测算说明 | R30: =G31*1.06 -> 7827.6442
C31: 总计 | D31: IT投入+CT投入+非IT/CT投入+综合类成本 | G31: =SUM(G11:G30) -> 7384.57 | Q31: =SUM(Q11:Q30) -> 7844 | R31: =Q31-6600000 -> -6592156 | S31: =R31-Q20 -> -6592156
A32: 评价参数 | C32: 折现率 | D32: 0.055 | J32: 净现金流量 | L32: 累计净现金流量 | M32: 净现金流量现值 | O32: 累计净现金流量现值 | R32: =Q31/1.06 -> 7400
A33: 项目年现金流 | C33: 第一年 | D33: 现金流入 | E33: =G10/3 -> 2691.93 | F33: 项目现金流出 | G33: =G31/3 -> 2461.52 | J33: =E33-G33 -> 230.41 | L33: =J33 -> 230.41 | M33: =J33/(1+D32)^1 -> 218.4 | O33: =J33/(1+D32)^1 -> 218.4 | Q33: =E33-E34 -> 0 | R33: =G33-G34 -> 0 | S33: =IF(O33<=0,100,O33/(#REF!-O33)) -> #REF! | T33: =IF(O33>=0,"T","F") -> T | U33: =IF(L33<=0,100,L33/(#REF!-L33)) -> #REF! | V33: =IF(L33>=0,"T","F") -> T
C34: 第二年 | D34: 现金流入 | E34: =G10/3 -> 2691.93 | F34: 项目现金流出 | G34: =G31/3 -> 2461.52 | J34: =E34-G34 -> 230.41 | L34: =L33+J34 -> 460.82 | M34: =J34/(1+D32)^2 -> 207.01 | O34: =O33+J34/(1+D32)^2 -> 425.41 | S34: =IF(O34<=0,100,O34/(O33-O34)) -> -2.06 | T34: =IF(O34>=0,"T","F") -> T | U34: =IF(L34<=0,100,L34/(L33-L34)) -> -2 | V34: =IF(L33<0,IF(L34>=0,"T","F"),"F") -> F
C35: 第三年 | D35: 现金流入 | E35: =G10/3 -> 2691.93 | F35: 项目现金流出 | G35: =G31/3 -> 2461.52 | J35: =E35-G35 -> 230.41 | L35: =L34+J35 -> 691.23 | M35: =J35/(1+D32)^3 -> 196.22 | O35: =O34+J35/(1+D32)^3 -> 621.63 | Q35: =ROUND(G33*1.06,2) -> 2609.21 | S35: =IF(O35<=0,100,O35/(O34-O35)) -> -3.17 | T35: =IF(O34<0,IF(O35>=0,"T","F"),"F") -> F | U35: =IF(L35<=0,100,L35/(L34-L35)) -> -3 | V35: =IF(L34<0,IF(L35>=0,"T","F"),"F") -> F
C36: 第四年 | D36: 现金流入 | F36: 项目现金流出 | J36: =E36-G36 -> 0 | L36: =L35+J36 -> 691.23 | M36: =J36/(1+D32)^4 -> 0 | O36: =O35+J36/(1+D32)^4 -> 621.63 | Q36: =ROUNDUP(G34*1.06,2) -> 2609.22 | S36: =IF(O36<=0,100,O36/(O35-O36)) -> #DIV/0! | T36: =IF(O35<0,IF(O36>=0,"T","F"),"F") -> F | U36: =IF(L36<=0,100,L36/(L35-L36)) -> #DIV/0! | V36: =IF(L35<0,IF(L36>=0,"T","F"),"F") -> F
C37: 第五年 | D37: 现金流入 | F37: 项目现金流出 | J37: =E37-G37 -> 0 | L37: =L36+J37 -> 691.23 | M37: =J37/(1+D32)^5 -> 0 | O37: =O36+J37/(1+D32)^5 -> 621.63 | Q37: =SUM(Q35:Q36) -> 5218.43 | S37: =IF(O37<=0,100,O37/(O36-O37)) -> #DIV/0! | T37: =IF(O36<0,IF(O37>=0,"T","F"),"F") -> F | U37: =IF(L37<=0,100,L37/(L36-L37)) -> #DIV/0! | V37: =IF(L36<0,IF(L37>=0,"T","F"),"F") -> F
C38: 第六年 | D38: 现金流入 | F38: 项目现金流出 | J38: =E38-G38 -> 0 | L38: =L37+J38 -> 691.23 | M38: =J38/(1+D32)^6 -> 0 | O38: =O37+J38/(1+D32)^6 -> 621.63 | S38: =IF(O38<=0,100,O38/(O37-O38)) -> #DIV/0! | T38: =IF(O37<0,IF(O38>=0,"T","F"),"F") -> F | U38: =IF(L38<=0,100,L38/(L37-L38)) -> #DIV/0! | V38: =IF(L37<0,IF(L38>=0,"T","F"),"F") -> F
C39: 第七年 | D39: 现金流入 | F39: 项目现金流出 | J39: =E39-G39 -> 0 | L39: =L38+J39 -> 691.23 | M39: =J39/(1+D32)^7 -> 0 | O39: =O38+J39/(1+D32)^7 -> 621.63 | S39: =IF(O39<=0,100,O39/(O38-O39)) -> #DIV/0! | T39: =IF(O38<0,IF(O39>=0,"T","F"),"F") -> F | U39: =IF(L39<=0,100,L39/(L38-L39)) -> #DIV/0! | V39: =IF(L38<0,IF(L39>=0,"T","F"),"F") -> F
C40: 第八年 | D40: 现金流入 | F40: 项目现金流出 | J40: =E40-G40 -> 0 | L40: =L39+J40 -> 691.23 | M40: =J40/(1+D32)^8 -> 0 | O40: =O39+J40/(1+D32)^8 -> 621.63 | S40: =IF(O40<=0,100,O40/(O39-O40)) -> #DIV/0! | T40: =IF(O39<0,IF(O40>=0,"T","F"),"F") -> F | U40: =IF(L40<=0,100,L40/(L39-L40)) -> #DIV/0! | V40: =IF(L39<0,IF(L40>=0,"T","F"),"F") -> F
...

Sheet 4-专线及各产品预算表
A1: 说明：需粘贴产品经理预算邮件回复/设计院专线建设勘察费用截图
A3: CT类别 | B3: 产品资费档次 | D3: 成本预算 （建设+维护） | F3: 合同签约单价 | H3: 签约数量
A4: 数智化转型咨询服务 | B4: 2640（不含税） | D4: 2640（不含税） | F4: 2640（不含税） | H4: 1
A5: 数据专线
A6: 云视讯
A7: 物联卡
A8: …

Sheet 5-标准产品投入和公允价值核算细则（如有更新，以更新后的规则）
A1: 产品名称 | C1: 投入核算规则 | D1: 公允价值
A2: 专线类 | B2: 数据专线 | C2: 建设投资+运营维护成本 20年全市平均建设成本：数据专线（城镇：4625元/条；农村：7242元/条；平均:5329元/条） 20年全市平均维护成本：285元/条/年 | D2: 本地专线按总部下发的目录价最低折扣0.7折计算。（政企通〔2021〕13 号） 跨省专线：按总部下发的刚性管控价计算。
B3: 互联网专线 | C3: 500M以下：建设投资+维护成本 500M及以上：按建设投资+维护成本+带宽价值底线价（5400元/1G/月） | D3: 按各带宽档次互联网专线基线价计算
B4: 企业宽带 | C4: 建设+装维+终端成本 安装费：城区58元/条，农村70元/条 维护费：2元/月/条 | D4: 100M-80元/月 200M-120元/月 500M-300元/月 1000M-600元 /月
B5: 智能组网 | C5: 终端设备成本：CMIOT-AX18-基础企业版，含税价203元 安装成本：城区58元/点位，农村70元/点位 无维护额外成本； | D5: 20元/月/点位
A6: 集团短彩信 | B6: 集团短彩信 | C6: 短信：0.04元/条 | D6: 短信：0.071元/条
B7: 云MAS | C7: 短信：0.04元/条 | D7: 短信：0.071元/条
B8: 5G多媒体消息 | C8: 本网：0.096元/条；异网：0.12元/条 | D8: 0.26元/条
A9: 集团语音 | C9: 呼叫中心：线路部分（同数据专线）+通信费（0.06元/分钟） 固话：线路部分（同数据专线）+话机 | D9: 呼叫中心：线路部分（同数据专线）+通信费（0.12元/分钟） 固话：按标准套餐档次（18-100元/月）+超套的通信费（0.10元/分钟） （注：通信费收入分摊结果不低于总部刚性管控价0.06元/分钟）
A10: 智能呼叫中心 | C10: 集团刚性管控：功能费+通信费（呼入呼出0.06元/分钟） | D10: 集团刚性管控：功能费+通信费（呼入呼出0.06元/分钟）
A11: 物联卡 | C11: 集团公司刚性管控底价 | D11: 按标准月资费计算 （注：收入分摊结果不低于集团公司刚性管控底价）
A12: 移动云 | C12: 标准产品：集团公司管控底价（现为5折） 特殊项目：市公司与云能中心单独核算 | D12: 按标准月资费计算 （注：收入分摊结果不低于集团公司管控底价，现在为5折，以最新文件为准）
A13: IDC | C13: 按投资+运营成本+带宽成本计算 | D13: 按每档次最低折扣价格计算： 机位服务（175元/月/U） 机柜服务（3450元/月/机架，4KW） 机柜服务（6034元/月/机架，7KW） 带宽价值：按IDC资费底价计算带宽价值。
A14: OneNET | C14: 按采购价格计算 | D14: 按标准售价计算
A15: 云视讯 | C15: 按终端+安装维护+终端延保成本计算 | D15: 按每款终端的标准月功能费计算
A16: 和对讲 | C16: 按终端采购成本计算 | D16: 按每款终端的标准月功能费计算（以和对讲指导意见发文为准）
A17: 千里眼 | C17: 按终端+安装维护+云存储成本+终端延保成本计算 | D17: 按每一型号的标准月功能费及云存储档次的月功能费计算
A18: 和商务TV | C18: 终端成本+牌照费（OTT：5.5元/月/户；IPTV：6.5元/月/户）+定制费成本 | D18: 按目录价20元/户/月计算+定制化成本
A19: 企业视频彩铃 | C19: 4元/户/月 | D19: 6元/户/月
A20: 移动办公 | C20: 按标准资费档次计算 云办公：按20元/户计算 | D20: 按标准资费档次计算 云办公：按20元/户计算
A21: 和交通 | B21: 车务通 | C21: 按终端采购成本计算 | D21: 按每款终端的标准月功能费计算（以车务通指导意见发文为准）
B22: 行车卫士 | C22: 按终端采购成本计算 | D22: 按每款终端的标准月功能费计算（以行车卫士指导意见发文为准）
B23: 高精度定位 | C23: 不低于与上研院结算（结算规则集团还在明确） | D23: 标准价格七折
A24: 大数据 | C24: 大数据短信：0.05元/条 | D24: 按标准销售价格计算
